Workbook

Sheet 원본파일
A2: 상가 | B2: 상호 | C2: 결제금액
A3: 거리 | B3: 썬데이키즈 | C3: 283000
A4: 거리 | B4: 씨티모자 | C4: 93000
A5: 거리 | B5: 엠버 | C5: 541000
A6: 거리 | B6: 월드모자 | C6: 236000
A7: 거리 | B7: 작은모자 | C7: 334000
A8: 거리 | B8: 팀앤드 | C8: 1414000
A9: 거리 | B9: 하모니 | C9: 114000
A10: 거리 | B10: 화이트스케치북 | C10: 6000000
A11: 마마 | B11: 구루구루 | C11: 88000
A12: 마마 | B12: 노멀플레이 | C12: 64000
A13: 마마 | B13: 디그린(악세10) | C13: 11759000
A14: 마마 | B14: 디스코봉봉 | C14: 182000
... A174: 혜양 | B174: 플라워제이 | C174: 1390000

Sheet 프린트(수정금지)
A1: =원본파일!A3 -> 거리 | B1: =원본파일!#REF! -> #REF! | C1: =원본파일!B3 -> 썬데이키즈 | D1: =원본파일!C3 -> 283000 | E1: =원본파일!#REF! -> #REF! | F1: =원본파일!#REF! -> #REF! | H1: =원본파일!A15 -> 마마 | I1: =원본파일!#REF! -> #REF! | J1: =원본파일!B15 -> 러브로지 | K1: =원본파일!C15 -> 30000 | L1: =원본파일!#REF! -> #REF! | M1: =원본파일!#REF! -> #REF!
A2: =원본파일!A4 -> 거리 | B2: =원본파일!#REF! -> #REF! | C2: =원본파일!B4 -> 씨티모자 | D2: =원본파일!C4 -> 93000 | E2: =원본파일!#REF! -> #REF! | F2: =원본파일!#REF! -> #REF! | H2: =원본파일!A16 -> 마마 | I2: =원본파일!#REF! -> #REF! | J2: =원본파일!B16 -> 리틀노말 | K2: =원본파일!C16 -> 37000 | L2: =원본파일!#REF! -> #REF! | M2: =원본파일!#REF! -> #REF!
A3: =원본파일!A5 -> 거리 | B3: =원본파일!#REF! -> #REF! | C3: =원본파일!B5 -> 엠버 | D3: =원본파일!C5 -> 541000 | E3: =원본파일!#REF! -> #REF! | F3: =원본파일!#REF! -> #REF! | H3: =원본파일!A17 -> 마마 | I3: =원본파일!#REF! -> #REF! | J3: =원본파일!B17 -> 메리고라운드 | K3: =원본파일!C17 -> 32000 | L3: =원본파일!#REF! -> #REF! | M3: =원본파일!#REF! -> #REF!
A4: =원본파일!A6 -> 거리 | B4: =원본파일!#REF! -> #REF! | C4: =원본파일!B6 -> 월드모자 | D4: =원본파일!C6 -> 236000 | E4: =원본파일!#REF! -> #REF! | F4: =원본파일!#REF! -> #REF! | H4: =원본파일!A18 -> 마마 | I4: =원본파일!#REF! -> #REF! | J4: =원본파일!B18 -> 모리모리 | K4: =원본파일!C18 -> 68000 | L4: =원본파일!#REF! -> #REF! | M4: =원본파일!#REF! -> #REF!
A5: =원본파일!A7 -> 거리 | B5: =원본파일!#REF! -> #REF! | C5: =원본파일!B7 -> 작은모자 | D5: =원본파일!C7 -> 334000 | E5: =원본파일!#REF! -> #REF! | F5: =원본파일!#REF! -> #REF! | H5: =원본파일!A19 -> 마마 | I5: =원본파일!#REF! -> #REF! | J5: =원본파일!B19 -> 모어 | K5: =원본파일!C19 -> 52000 | L5: =원본파일!#REF! -> #REF! | M5: =원본파일!#REF! -> #REF!
A6: =원본파일!A8 -> 거리 | B6: =원본파일!#REF! -> #REF! | C6: =원본파일!B8 -> 팀앤드 | D6: =원본파일!C8 -> 1414000 | E6: =원본파일!#REF! -> #REF! | F6: =원본파일!#REF! -> #REF! | H6: =원본파일!A20 -> 마마 | I6: =원본파일!#REF! -> #REF! | J6: =원본파일!B20 -> 미니로브(악세10) | K6: =원본파일!C20 -> 31228000 | L6: =원본파일!#REF! -> #REF! | M6: =원본파일!#REF! -> #REF!
A7: =원본파일!A9 -> 거리 | B7: =원본파일!#REF! -> #REF! | C7: =원본파일!B9 -> 하모니 | D7: =원본파일!C9 -> 114000 | E7: =원본파일!#REF! -> #REF! | F7: =원본파일!#REF! -> #REF! | H7: =원본파일!A21 -> 마마 | I7: =원본파일!#REF! -> #REF! | J7: =원본파일!B21 -> 미니멜로 | K7: =원본파일!C21 -> 32000 | L7: =원본파일!#REF! -> #REF! | M7: =원본파일!#REF! -> #REF!
A8: =원본파일!A10 -> 거리 | B8: =원본파일!#REF! -> #REF! | C8: =원본파일!B10 -> 화이트스케치북 | D8: =원본파일!C10 -> 6000000 | E8: =원본파일!#REF! -> #REF! | F8: =원본파일!#REF! -> #REF! | H8: =원본파일!A22 -> 마마 | I8: =원본파일!#REF! -> #REF! | J8: =원본파일!B22 -> 베베홀릭 | K8: =원본파일!C22 -> 2000000 | L8: =원본파일!#REF! -> #REF! | M8: =원본파일!#REF! -> #REF!
A9: =원본파일!A11 -> 마마 | B9: =원본파일!#REF! -> #REF! | C9: =원본파일!B11 -> 구루구루 | D9: =원본파일!C11 -> 88000 | E9: =원본파일!#REF! -> #REF! | F9: =원본파일!#REF! -> #REF! | H9: =원본파일!A23 -> 마마 | I9: =원본파일!#REF! -> #REF! | J9: =원본파일!B23 -> 벨로 | K9: =원본파일!C23 -> 930000 | L9: =원본파일!#REF! -> #REF! | M9: =원본파일!#REF! -> #REF!
A10: =원본파일!A12 -> 마마 | B10: =원본파일!#REF! -> #REF! | C10: =원본파일!B12 -> 노멀플레이 | D10: =원본파일!C12 -> 64000 | E10: =원본파일!#REF! -> #REF! | F10: =원본파일!#REF! -> #REF! | H10: =원본파일!A24 -> 마마 | I10: =원본파일!#REF! -> #REF! | J10: =원본파일!B24 -> 벨루베베 | K10: =원본파일!C24 -> 5755000 | L10: =원본파일!#REF! -> #REF! | M10: =원본파일!#REF! -> #REF!
A11: =원본파일!A13 -> 마마 | B11: =원본파일!#REF! -> #REF! | C11: =원본파일!B13 -> 디그린(악세10) | D11: =원본파일!C13 -> 11759000 | E11: =원본파일!#REF! -> #REF! | F11: =원본파일!#REF! -> #REF! | H11: =원본파일!A25 -> 마마 | I11: =원본파일!#REF! -> #REF! | J11: =원본파일!B25 -> 브로디제인 | K11: =원본파일!C25 -> 262000 | L11: =원본파일!#REF! -> #REF! | M11: =원본파일!#REF! -> #REF!
A12: =원본파일!A14 -> 마마 | B12: =원본파일!#REF! -> #REF! | C12: =원본파일!B14 -> 디스코봉봉 | D12: =원본파일!C14 -> 182000 | E12: =원본파일!#REF! -> #REF! | F12: =원본파일!#REF! -> #REF! | H12: =원본파일!A26 -> 마마 | I12: =원본파일!#REF! -> #REF! | J12: =원본파일!B26 -> 아커 | K12: =원본파일!C26 -> 76000 | L12: =원본파일!#REF! -> #REF! | M12: =원본파일!#REF! -> #REF!
A13: =원본파일!A27 -> 마마 | B13: =원본파일!#REF! -> #REF! | C13: =원본파일!B27 -> 아토메메(악세10) | D13: =원본파일!C27 -> 13498000 | E13: =원본파일!#REF! -> #REF! | F13: =원본파일!#REF! -> #REF! | H13: =원본파일!A39 -> 부르뎅 | I13: =원본파일!#REF! -> #REF! | J13: =원본파일!B39 -> 도레도레 | K13: =원본파일!C39 -> 2917000 | L13: =원본파일!#REF! -> #REF! | M13: =원본파일!#REF! -> #REF!
A14: =원본파일!A28 -> 마마 | B14: =원본파일!#REF! -> #REF! | C14: =원본파일!B28 -> 에끌레어 | D14: =원본파일!C28 -> 696000 | E14: =원본파일!#REF! -> #REF! | F14: =원본파일!#REF! -> #REF! | H14: =원본파일!A40 -> 부르뎅 | I14: =원본파일!#REF! -> #REF! | J14: =원본파일!B40 -> 러빈 | K14: =원본파일!C40 -> 61000 | L14: =원본파일!#REF! -> #REF! | M14: =원본파일!#REF! -> #REF!
A15: =원본파일!A29 -> 마마 | B15: =원본파일!#REF! -> #REF! | C15: =원본파일!B29 -> 엘리몰리 | D15: =원본파일!C29 -> 89000 | E15: =원본파일!#REF! -> #REF! | F15: =원본파일!#REF! -> #REF! | H15: =원본파일!A41 -> 부르뎅 | I15: =원본파일!#REF! -> #REF! | J15: =원본파일!B41 -> 레이커 | K15: =원본파일!C41 -> 59000 | L15: =원본파일!#REF! -> #REF! | M15: =원본파일!#REF! -> #REF!
A16: =원본파일!A30 -> 마마 | B16: =원본파일!#REF! -> #REF! | C16: =원본파일!B30 -> 오렌 | D16: =원본파일!C30 -> 902000 | E16: =원본파일!#REF! -> #REF! | F16: =원본파일!#REF! -> #REF! | H16: =원본파일!A42 -> 부르뎅 | I16: =원본파일!#REF! -> #REF! | J16: =원본파일!B42 -> 로다제이 | K16: =원본파일!C42 -> 33000 | L16: =원본파일!#REF! -> #REF! | M16: =원본파일!#REF! -> #REF!
A17: =원본파일!A31 -> 마마 | B17: =원본파일!#REF! -> #REF! | C17: =원본파일!B31 -> 이지아이(주언사JU) | D17: =원본파일!C31 -> 346000 | E17: =원본파일!#REF! -> #REF! | F17: =원본파일!#REF! -> #REF! | H17: =원본파일!A43 -> 부르뎅 | I17: =원본파일!#REF! -> #REF! | J17: =원본파일!B43 -> 멜멜 | K17: =원본파일!C43 -> 860000 | L17: =원본파일!#REF! -> #REF! | M17: =원본파일!#REF! -> #REF!
A18: =원본파일!A32 -> 마마 | B18: =원본파일!#REF! -> #REF! | C18: =원본파일!B32 -> 재주소년 | D18: =원본파일!C32 -> 631000 | E18: =원본파일!#REF! -> #REF! | F18: =원본파일!#REF! -> #REF! | H18: =원본파일!A44 -> 부르뎅 | I18: =원본파일!#REF! -> #REF! | J18: =원본파일!B44 -> 몽쉘슈슈 | K18: =원본파일!C44 -> 31000 | L18: =원본파일!#REF! -> #REF! | M18: =원본파일!#REF! -> #REF!
A19: =원본파일!A33 -> 마마 | B19: =원본파일!#REF! -> #REF! | C19: =원본파일!B33 -> 폼 | D19: =원본파일!C33 -> 193000 | E19: =원본파일!#REF! -> #REF! | F19: =원본파일!#REF! -> #REF! | H19: =원본파일!A45 -> 부르뎅 | I19: =원본파일!#REF! -> #REF! | J19: =원본파일!B45 -> 미앙블룸비 | K19: =원본파일!C45 -> 288000 | L19: =원본파일!#REF! -> #REF! | M19: =원본파일!#REF! -> #REF!
A20: =원본파일!A34 -> 마마 | B20: =원본파일!#REF! -> #REF! | C20: =원본파일!B34 -> 퐁듀 | D20: =원본파일!C34 -> 264000 | E20: =원본파일!#REF! -> #REF! | F20: =원본파일!#REF! -> #REF! | H20: =원본파일!A46 -> 부르뎅 | I20: =원본파일!#REF! -> #REF! | J20: =원본파일!B46 -> 보보제이 | K20: =원본파일!C46 -> 1459000 | L20: =원본파일!#REF! -> #REF! | M20: =원본파일!#REF! -> #REF!
A21: =원본파일!A35 -> 마마 | B21: =원본파일!#REF! -> #REF! | C21: =원본파일!B35 -> 푸이푸이 | D21: =원본파일!C35 -> 72000 | E21: =원본파일!#REF! -> #REF! | F21: =원본파일!#REF! -> #REF! | H21: =원본파일!A47 -> 부르뎅 | I21: =원본파일!#REF! -> #REF! | J21: =원본파일!B47 -> 세븐틴 | K21: =원본파일!C47 -> 71000 | L21: =원본파일!#REF! -> #REF! | M21: =원본파일!#REF! -> #REF!
A22: =원본파일!A36 -> 마마 | B22: =원본파일!#REF! -> #REF! | C22: =원본파일!B36 -> 플로 | D22: =원본파일!C36 -> 6826000 | E22: =원본파일!#REF! -> #REF! | F22: =원본파일!#REF! -> #REF! | H22: =원본파일!A48 -> 부르뎅 | I22: =원본파일!#REF! -> #REF! | J22: =원본파일!B48 -> 스마일허그(구야누스) | K22: =원본파일!C48 -> 124000 | L22: =원본파일!#REF! -> #REF! | M22: =원본파일!#REF! -> #REF!
A23: =원본파일!A37 -> 마마 | B23: =원본파일!#REF! -> #REF! | C23: =원본파일!B37 -> 허니팟 | D23: =원본파일!C37 -> 47000 | E23: =원본파일!#REF! -> #REF! | F23: =원본파일!#REF! -> #REF! | H23: =원본파일!A49 -> 부르뎅 | I23: =원본파일!#REF! -> #REF! | J23: =원본파일!B49 -> 아오스타 | K23: =원본파일!C49 -> 382000 | L23: =원본파일!#REF! -> #REF! | M23: =원본파일!#REF! -> #REF!
A24: =원본파일!A38 -> 마마 | B24: =원본파일!#REF! -> #REF! | C24: =원본파일!B38 -> 히얼아이엠 | D24: =원본파일!C38 -> 16630000 | E24: =원본파일!#REF! -> #REF! | F24: =원본파일!#REF! -> #REF! | H24: =원본파일!A50 -> 부르뎅 | I24: =원본파일!#REF! -> #REF! | J24: =원본파일!B50 -> 아이아이/마이다럴 | K24: =원본파일!C50 -> 5626000 | L24: =원본파일!#REF! -> #REF! | M24: =원본파일!#REF! -> #REF!
A25: =원본파일!A51 -> 부르뎅 | B25: =원본파일!#REF! -> #REF! | C25: =원본파일!B51 -> 알라딘 | D25: =원본파일!C51 -> 89000 | E25: =원본파일!#REF! -> #REF! | F25: =원본파일!#REF! -> #REF! | H25: =원본파일!A63 -> 씨티 | I25: =원본파일!#REF! -> #REF! | J25: =원본파일!B63 -> 미니포인트 | K25: =원본파일!C63 -> 273000 | L25: =원본파일!#REF! -> #REF! | M25: =원본파일!#REF! -> #REF!
A26: =원본파일!A52 -> 부르뎅 | B26: =원본파일!#REF! -> #REF! | C26: =원본파일!B52 -> 엠키즈 | D26: =원본파일!C52 -> 1057000 | E26: =원본파일!#REF! -> #REF! | F26: =원본파일!#REF! -> #REF! | H26: =원본파일!A64 -> 씨티 | I26: =원본파일!#REF! -> #REF! | J26: =원본파일!B64 -> 밀크밤 | K26: =원본파일!C64 -> 49000 | L26: =원본파일!#REF! -> #REF! | M26: =원본파일!#REF! -> #REF!
A27: =원본파일!A53 -> 부르뎅 | B27: =원본파일!#REF! -> #REF! | C27: =원본파일!B53 -> 이루 | D27: =원본파일!C53 -> 196000 | E27: =원본파일!#REF! -> #REF! | F27: =원본파일!#REF! -> #REF! | H27: =원본파일!A65 -> 씨티 | I27: =원본파일!#REF! -> #REF! | J27: =원본파일!B65 -> 바나나제이 | K27: =원본파일!C65 -> 136000 | L27: =원본파일!#REF! -> #REF! | M27: =원본파일!#REF! -> #REF!
A28: =원본파일!A54 -> 부르뎅 | B28: =원본파일!#REF! -> #REF! | C28: =원본파일!B54 -> 크림빵 | D28: =원본파일!C54 -> 277000 | E28: =원본파일!#REF! -> #REF! | F28: =원본파일!#REF! -> #REF! | H28: =원본파일!A66 -> 씨티 | I28: =원본파일!#REF! -> #REF! | J28: =원본파일!B66 -> 바이미미 | K28: =원본파일!C66 -> 209000 | L28: =원본파일!#REF! -> #REF! | M28: =원본파일!#REF! -> #REF!
A29: =원본파일!A55 -> 부르뎅 | B29: =원본파일!#REF! -> #REF! | C29: =원본파일!B55 -> 헤이 | D29: =원본파일!C55 -> 579000 | E29: =원본파일!#REF! -> #REF! | F29: =원본파일!#REF! -> #REF! | H29: =원본파일!A67 -> 씨티 | I29: =원본파일!#REF! -> #REF! | J29: =원본파일!B67 -> 버니파우더 | K29: =원본파일!C67 -> 148000 | L29: =원본파일!#REF! -> #REF! | M29: =원본파일!#REF! -> #REF!
A30: =원본파일!A56 -> 씨티 | B30: =원본파일!#REF! -> #REF! | C30: =원본파일!B56 -> 니니벨로 | D30: =원본파일!C56 -> 12390000 | E30: =원본파일!#REF! -> #REF! | F30: =원본파일!#REF! -> #REF! | H30: =원본파일!A68 -> 씨티 | I30: =원본파일!#REF! -> #REF! | J30: =원본파일!B68 -> 베베나인베베 | K30: =원본파일!C68 -> 45000 | L30: =원본파일!#REF! -> #REF! | M30: =원본파일!#REF! -> #REF!
A31: =원본파일!A57 -> 씨티 | B31: =원본파일!#REF! -> #REF! | C31: =원본파일!B57 -> 더랄라 | D31: =원본파일!C57 -> 2711000 | E31: =원본파일!#REF! -> #REF! | F31: =원본파일!#REF! -> #REF! | H31: =원본파일!A69 -> 씨티 | I31: =원본파일!#REF! -> #REF! | J31: =원본파일!B69 -> 베이블리 | K31: =원본파일!C69 -> 1785000 | L31: =원본파일!#REF! -> #REF! | M31: =원본파일!#REF! -> #REF!
A32: =원본파일!A58 -> 씨티 | B32: =원본파일!#REF! -> #REF! | C32: =원본파일!B58 -> 라라봉봉 | D32: =원본파일!C58 -> 487000 | E32: =원본파일!#REF! -> #REF! | F32: =원본파일!#REF! -> #REF! | H32: =원본파일!A70 -> 씨티 | I32: =원본파일!#REF! -> #REF! | J32: =원본파일!B70 -> 보니토(악세10) | K32: =원본파일!C70 -> 1607000 | L32: =원본파일!#REF! -> #REF! | M32: =원본파일!#REF! -> #REF!
A33: =원본파일!A59 -> 씨티 | B33: =원본파일!#REF! -> #REF! | C33: =원본파일!B59 -> 로그101 | D33: =원본파일!C59 -> 74000 | E33: =원본파일!#REF! -> #REF! | F33: =원본파일!#REF! -> #REF! | H33: =원본파일!A71 -> 씨티 | I33: =원본파일!#REF! -> #REF! | J33: =원본파일!B71 -> 빠빠 | K33: =원본파일!C71 -> 1291000 | L33: =원본파일!#REF! -> #REF! | M33: =원본파일!#REF! -> #REF!
A34: =원본파일!A60 -> 씨티 | B34: =원본파일!#REF! -> #REF! | C34: =원본파일!B60 -> 마틸다앤리 | D34: =원본파일!C60 -> 341000 | E34: =원본파일!#REF! -> #REF! | F34: =원본파일!#REF! -> #REF! | H34: =원본파일!A72 -> 씨티 | I34: =원본파일!#REF! -> #REF! | J34: =원본파일!B72 -> 세인트돌 | K34: =원본파일!C72 -> 143000 | L34: =원본파일!#REF! -> #REF! | M34: =원본파일!#REF! -> #REF!
A35: =원본파일!A61 -> 씨티 | B35: =원본파일!#REF! -> #REF! | C35: =원본파일!B61 -> 모메 | D35: =원본파일!C61 -> 67000 | E35: =원본파일!#REF! -> #REF! | F35: =원본파일!#REF! -> #REF! | H35: =원본파일!A73 -> 씨티 | I35: =원본파일!#REF! -> #REF! | J35: =원본파일!B73 -> 스튜디오엠 | K35: =원본파일!C73 -> 185000 | L35: =원본파일!#REF! -> #REF! | M35: =원본파일!#REF! -> #REF!
A36: =원본파일!A62 -> 씨티 | B36: =원본파일!#REF! -> #REF! | C36: =원본파일!B62 -> 미니멀 | D36: =원본파일!C62 -> 5404000 | E36: =원본파일!#REF! -> #REF! | F36: =원본파일!#REF! -> #REF! | H36: =원본파일!A74 -> 씨티 | I36: =원본파일!#REF! -> #REF! | J36: =원본파일!B74 -> 아오유스튜디오 | K36: =원본파일!C74 -> 3402000 | L36: =원본파일!#REF! -> #REF! | M36: =원본파일!#REF! -> #REF!
A37: =원본파일!A75 -> 씨티 | B37: =원본파일!#REF! -> #REF! | C37: =원본파일!B75 -> 앤드버터 | D37: =원본파일!C75 -> 32000 | E37: =원본파일!#REF! -> #REF! | F37: =원본파일!#REF! -> #REF! | H37: =원본파일!A87 -> 웅이 | I37: =원본파일!#REF! -> #REF! | J37: =원본파일!B87 -> 모란 | K37: =원본파일!C87 -> 1943000 | L37: =원본파일!#REF! -> #REF! | M37: =원본파일!#REF! -> #REF!
A38: =원본파일!A76 -> 씨티 | B38: =원본파일!#REF! -> #REF! | C38: =원본파일!B76 -> 에이모어 | D38: =원본파일!C76 -> 295000 | E38: =원본파일!#REF! -> #REF! | F38: =원본파일!#REF! -> #REF! | H38: =원본파일!A88 -> 웅이 | I38: =원본파일!#REF! -> #REF! | J38: =원본파일!B88 -> 미라이키 | K38: =원본파일!C88 -> 787000 | L38: =원본파일!#REF! -> #REF! | M38: =원본파일!#REF! -> #REF!
A39: =원본파일!A77 -> 씨티 | B39: =원본파일!#REF! -> #REF! | C39: =원본파일!B77 -> 제이룸 | D39: =원본파일!C77 -> 265000 | E39: =원본파일!#REF! -> #REF! | F39: =원본파일!#REF! -> #REF! | H39: =원본파일!A89 -> 웅이 | I39: =원본파일!#REF! -> #REF! | J39: =원본파일!B89 -> 미소 | K39: =원본파일!C89 -> 1048000 | L39: =원본파일!#REF! -> #REF! | M39: =원본파일!#REF! -> #REF!
A40: =원본파일!A78 -> 씨티 | B40: =원본파일!#REF! -> #REF! | C40: =원본파일!B78 -> 키들리 | D40: =원본파일!C78 -> 649000 | E40: =원본파일!#REF! -> #REF! | F40: =원본파일!#REF! -> #REF! | H40: =원본파일!A90 -> 웅이 | I40: =원본파일!#REF! -> #REF! | J40: =원본파일!B90 -> 보네오네 | K40: =원본파일!C90 -> 263000 | L40: =원본파일!#REF! -> #REF! | M40: =원본파일!#REF! -> #REF!
...
